Workbook

Sheet Instructions
A1: Philadelphia S-Corp vs LLC Tax Model
A2: Planning model for a single Philadelphia resident owner. Blue/yellow cells are editable inputs.
A4: How to use
A5: 1. Review the Assumptions sheet first.
A6: 2. Enter your facts on the SCorp and LLC_Individual sheets in blue/yellow cells only.
A7: 3. The model keeps business-level deductions separate from owner-level taxes.
A8: 4. BIRT is modeled as a business-level cost; PA PIT, Wage Tax, and NPT are modeled at the owner level.
A9: 5. Federal tax is estimated using 2026 single brackets and a simplified QBI calculation.
A10: 6. This workbook is for planning only and is not a filing-ready tax return.
A12: Color key
A13: • Blue font on yellow fill = user input
A14: • Black font = formula / calculation
... A21: • Does not include SSTB phaseouts, UBIA limits, or multi-state sourcing.

Sheet Assumptions
A1: Assumptions
A2: Review highlighted assumptions before using the structure tabs.
A4: Core Assumptions
A5: Tax Year | B5: 2026 | C5: Static | D5: Planning model uses 2026 rules.
A6: Federal filing status | B6: Single | C6: Static | D6: Model is built for 2026 single-filer brackets.
A7: Gross revenue | B7: 1000000 | C7: Input | D7: Current 2026 amount.
A8: Ordinary operating expenses | B8: 600000 | C8: Input | D8: Current 2026 amount.
A9: Federal standard deduction | B9: 16100 | C9: Input | D9: Current 2026 amount.
A10: PA PIT rate | B10: 0.0307 | C10: Input | D10: PA personal income tax rate.
A11: Philadelphia resident Wage Tax rate | B11: 0.0374 | C11: Input | D11: Resident wage tax rate.
A12: Philadelphia resident NPT rate | B12: 0.0374 | C12: Input | D12: Resident net profits tax rate.
A13: Philadelphia SIT _Scorp | B13: 0.0374 | C13: Input | D13: Resident School Tax
A14: Federal SALT cap | B14: 40400 | C14: Input | D14: 2026 cap under current law.
A15: SALT phase-down threshold | B15: 505000 | C15: Input | D15: 2026 threshold under current law.
A16: SALT floor | B16: 10000 | C16: Input | D16: Minimum SALT deduction after phase-down.
A17: QBI deduction rate | B17: 0.2 | C17: Input | D17: Simplified Section 199A rate.
A18: SE tax adjustment factor | B18: 0.9235 | C18: Input | D18: Schedule SE net earnings factor.
... A35: QBI phaseout upper, single | B35: 276750 | C35: Input | D35: 2026 phase-in range upper bound for all other returns.
A36: 2026 Federal Single Brackets
F37: Bracket | G37: Lower bound | H37: Upper bound | I37: Rate | J37: Base tax at lower bound
F38: 10% | G38: 0 | H38: 12400 | I38: 0.1 | J38: 0
F39: 12% | G39: 12400 | H39: 50400 | I39: 0.12 | J39: =J38+(H38-G38)*I38 -> 1240
F40: 22% | G40: 50400 | H40: 105700 | I40: 0.22 | J40: =J39+(H39-G39)*I39 -> 5800
F41: 24% | G41: 105700 | H41: 201775 | I41: 0.24 | J41: =J40+(H40-G40)*I40 -> 17966
F42: 32% | G42: 201775 | H42: 256225 | I42: 0.32 | J42: =J41+(H41-G41)*I41 -> 41024
F43: 35% | G43: 256225 | H43: 640600 | I43: 0.35 | J43: =J42+(H42-G42)*I42 -> 58448
F44: 37% | G44: 640600 | H44: 1000000000000 | I44: 0.37 | J44: =J43+(H43-G43)*I43 -> 192979.25

Sheet Compare
A1: Comparison Summary
A2: Compare business-level tax, owner-level taxes, and approximate after-tax income.
A4: Comparison
A5: Metric | B5: S-Corp | C5: LLC | D5: Difference (S-Corp - LLC)
A6: Business-level tax: BIRT | B6: =SCorp!B71 -> 16675.685 | C6: =LLC_Individual!B65 -> 0 | D6: =B6-C6 -> 16675.685
A7: Owner-level tax: PA PIT | B7: =SCorp!B72 -> 11234.358 | C7: =LLC_Individual!B66 -> 12280 | D7: =B7-C7 -> -1045.642
A8: Owner-level tax: Philadelphia tax - SIT, Wage and NPT | B8: =SCorp!B74+SCorp!B73 -> 13115.219 | C8: =LLC_Individual!B67 -> 14960 | D8: =B8-C8 -> -1844.7806
A9: Owner-level tax: Payroll / SE taxes | B9: =SCorp!B75 -> 7650 | C9: =LLC_Individual!B68 -> 35115.2 | D9: =B9-C9 -> -27465.2
A10: Owner-level tax: Estimated federal income tax | B10: =SCorp!B76 -> 57039.916 | C10: =LLC_Individual!B69 -> 68156.895 | D10: =B10-C10 -> -11116.979
A11: Estimated total owner level tax burden | B11: =SCorp!B77 -> 89039.493 | C11: =LLC_Individual!B70 -> 130512.1 | D11: =B11-C11 -> -41472.602
A12: Approx. after-tax income | B12: =SCorp!B78 -> 237134.82 | C12: =LLC_Individual!B71 -> 197487.9 | D12: =B12-C12 -> 39646.917
A13: Approx. after-tax income + retirement benefits | B13: =SCorp!B80 -> 286634.82 | C13: =LLC_Individual!B73 -> 269487.91 | D13: =B13-C13 -> 17146.917
A16: Notes
A17: • BIRT is treated as a business-level cost in S-Corp - BIRT is exempt for LLC
A18: • S-corp owner-level payroll taxes include employee-side payroll taxes only; employer payroll taxes are already embedded in business results.
A19: • QBI now includes 2026 single-filer threshold / phase-in logic, SSTB toggle, W-2 wage limit, and UBIA input.
A20: • Federal bracket tax assumes ordinary taxable income only. Preferential capital-gain tax rates are not modeled.

Sheet SCorp
A1: S-Corp Model
A2: Blue/yellow cells are user inputs. Model assumes one shareholder and Philadelphia resident rates.
A4: Assumptions
A5: Gross revenue | B5: =Assumptions!B7 -> 1000000
A6: Ordinary operating expenses | B6: =Assumptions!B8 -> 600000
A7: Employee 401(k) deferral | B7: =Assumptions!B30 -> 24500
A8: Employer retirement contribution | B8: =MIN(0.25*B11,Assumptions!B31-SCorp!B7) -> 25000
A9: SSTB? 1=yes, 0=no | B9: =Assumptions!B33 -> 0
A10: Inputs
A11: Shareholder W-2 gross wages | B11: 100000
A12: Other business adjustments | B12: 0
A13: Other ordinary income (no cap gains / qual divs) | B13: 0
A14: Other itemized deductions (non-SALT) | B14: 0
A15: QBI
A16: QBI W-2 wages for limit | B16: =B11 -> 100000
A17: UBIA of qualified property | B17: 0
A18: Net cap gain + qual dividends (for QBI cap only) | B18: 0
A19: Business-Level Calculation
A20: W-2 Box 1 wages | B20: =B11-B7 -> 75500
A21: Employer Social Security tax | B21: =MIN(B11,Assumptions!$B$26)*Assumptions!$B$24 -> 6200
A22: Employer Medicare tax | B22: =B11*Assumptions!$B$25 -> 1450
A23: Total employer payroll tax | B23: =SUM(B21:B22) -> 7650
A24: Pre-BIRT net income | B24: =B5-B6-B11-B23-B8-B12 -> 267350
A25: BIRT gross receipts tax | B25: =B5*Assumptions!$B$28 -> 1410
A26: BIRT net income tax | B26: =MAX(0,B24)*Assumptions!$B$29 -> 15265.685
A27: Total BIRT | B27: =SUM(B25:B26) -> 16675.685
A28: Final pass-through income (K-1 ordinary) | B28: =B24-B27 -> 250674.32
A30: Owner-Level State / City / Payroll Taxes
A31: PA taxable wages | B31: =B11 -> 100000
A32: PA taxable S-corp income | B32: =B24-B25 -> 265940
A33: PA PIT | B33: =MAX(0,B31+B32)*Assumptions!$B$10 -> 11234.358
A34: Philadelphia Wage Tax | B34: =B11*Assumptions!$B$11 -> 3740
A35: Philadelphia SIT | B35: =B28*Assumptions!B13 -> 9375.2194
A36: Philadelphia NPT | B36: =0 -> 0
A37: Employee Social Security tax | B37: =MIN(B11,Assumptions!$B$26)*Assumptions!$B$21 -> 6200
A38: Employee Medicare tax | B38: =B11*Assumptions!$B$22 -> 1450
A39: Additional Medicare tax | B39: =MAX(0,B11-Assumptions!$B$27)*Assumptions!$B$23 -> 0
A40: Total employee payroll taxes | B40: =SUM(B37:B39) -> 7650
A42: Federal AGI, Deductions, QBI, and Income Tax
A43: W-2 Box 1 wages | B43: =B20 -> 75500
...

Sheet LLC_Individual
A1: LLC Taxed as Individual Model
A2: Blue/yellow cells are user inputs. Model assumes a disregarded single-member LLC.
A4: Assumptions
A5: Gross revenue | B5: =Assumptions!B7 -> 1000000
A6: Ordinary operating expenses | B6: =Assumptions!B8 -> 600000
A7: Employee 401(k) deferral | B7: =MIN(Assumptions!B30,MAX(0,B37)) -> 24500
A8: Self-employed retirement contribution | B8: =MIN(Assumptions!B31,(LLC_Individual!B7+(Assumptions!B32*LLC_Individual!B37))) -> 72000
A9: SSTB? 1=yes, 0=no | B9: =Assumptions!B33 -> 0
A10: Inputs
A11: Other business adjustments | B11: 0
A12: Other ordinary income (no cap gains / qual divs) | B12: 0
A13: Other itemized deductions (non-SALT) | B13: 0
A14: QBI
A15: QBI W-2 wages for limit | B15: 0
A16: UBIA of qualified property | B16: 0
A17: Net cap gain + qual dividends (for QBI cap only) | B17: 0
A18: Business-Level Calculation
A19: Pre-BIRT net income | B19: =B5-B6-B11 -> 400000
A20: Final Schedule C profit | B20: =B19 -> 400000
A22: Self-Employment Tax
A23: SE income subject to SE tax | B23: =MAX(0,B20)*Assumptions!$B$18 -> 369400
A24: SE Social Security tax | B24: =MIN(B23,Assumptions!$B$26)*Assumptions!$B$19 -> 22878
A25: SE Medicare tax | B25: =B23*Assumptions!$B$20 -> 10712.6
A26: Additional Medicare tax (simplified) | B26: =MAX(0,B23-Assumptions!$B$27)*Assumptions!$B$23 -> 1524.6
A27: Total SE / Medicare taxes | B27: =SUM(B24:B26) -> 35115.2
A28: Deduction for 1/2 SE tax | B28: =(B24+B25)/2 -> 16795.3
A30: Owner-Level State / City Taxes
A31: PA PIT | B31: =MAX(0,B20)*Assumptions!$B$10 -> 12280
A32: Philadelphia NPT | B32: =MAX(0,B20)*Assumptions!$B$12 -> 14960
A34: Federal AGI, Deductions, QBI, and Income Tax
A35: Schedule C profit | B35: =B20 -> 400000
A36: Less 1/2 SE tax deduction | B36: =B28 -> 16795.3
A37: Earned Income Before Retirement | B37: =B35-B36 -> 383204.7
A38: Less self-employed retirement | B38: =B8 -> 72000
A39: Other personal income | B39: =B12 -> 0
A40: Federal AGI before itemized / standard | B40: =B37-B38+B39 -> 311204.7
A41: SALT paid | B41: =B31+B32 -> 27240
A42: Allowed SALT cap | B42: =MAX(Assumptions!$B$16,Assumptions!$B$14-0.3*MAX(0,B40-Assumptions!$B$15)) -> 40400
A43: Allowed SALT deduction | B43: =MIN(B41,B42) -> 27240
A44: Itemized deductions total | B44: =B43+B13 -> 27240
...

Sheet Sources
A1: Source URLs
A2: Plain-text URLs used for current assumptions and notes.
A4: Item | B4: URL | C4: Retrieved | D4: Notes
A5: IRS 2026 inflation adjustments | B5: https://www.irs.gov/newsroom/irs-releases-tax-inflation-adjustments-for-tax-year-2026-including-amendments-from-the-one-big-beautiful-bill | C5: 2026-04-06 | D5: Standard deduction and single brackets
A6: PA PIT overview | B6: https://www.pa.gov/agencies/revenue/resources/tax-types-and-information/personal-income-tax | C6: 2026-04-06 | D6: PA PIT rate 3.07%
A7: Philadelphia Wage Tax | B7: https://www.phila.gov/services/payments-assistance-taxes/taxes/business-taxes/business-taxes-by-type/wage-tax-employers/ | C7: 2026-04-06 | D7: Resident wage tax rate 3.74%
A8: Philadelphia NPT | B8: https://www.phila.gov/services/payments-assistance-taxes/taxes/business-taxes/business-taxes-by-type/net-profits-tax/ | C8: 2026-04-06 | D8: Resident NPT rate 3.74% and LLC applicability
A9: Philadelphia BIRT | B9: https://www.phila.gov/services/payments-assistance-taxes/taxes/business-taxes/business-taxes-by-type/business-income-receipts-tax-birt/ | C9: 2026-04-06 | D9: BIRT rates and BIRT separate from NPT
A10: SALT overview | B10: https://tax.thomsonreuters.com/en/glossary/salt-deduction | C10: 2026-04-06 | D10: 2026 SALT cap / phase-down overview
A11: SALT law explainer | B11: https://bipartisanpolicy.org/article/how-would-the-2025-house-tax-bill-change-the-salt-deduction/ | C11: 2026-04-06 | D11: 40,400 cap and 505,000 threshold
